Workbook
Name Slicer_Representative: #N/A

Sheet Call_Data_Table_Sheet
A1: Call Centre Data
A2: Call number | B2: Customer ID | C2: Duration | D2: Representative | E2: Date of Call | F2: Purchase Amount | G2: Satisfaction Rating | H2: Finacial Year | I2: Day of Week | J2: Duration Bucket in Hours | K2: Rating Rounded | N2: Customer ID | O2: Gedner | P2: Age | Q2: City
A3: Call_7271 | B3: C0003 | C3: 116 | D3: R05 | E3: 44927 | F3: 128 | G3: 4.9 | H3: =IF(MONTH(Call_Table_Data[[#This Row],[Date of Call]])<=3,YEAR(Call_Table_Data[[#This Row],[Date of Call]]),YEAR(Call_Table_Data[[#This Row],[Date of Call]])+1) -> 2023 | I3: =TEXT(Call_Table_Data[[#This Row],[Date of Call]],"DDDD") -> Sunday | J3: {=_xlfn.IFS(Call_Table_Data[[#This Row],[Duration]]<=10,"Under 10 Mins",Call_Table_Data[[#This Row],[Duration]]<=30,"10 to 30 Mins",Call_Table_Data[[#This Row],[Duration]]<=60,"30 to 60 Mins",Call_Table_Data[[#This Row],[Duration]]<=120,"1 to 2 Hours",TRUE,"More Than 2 Hours")} -> 1 to 2 Hours | K3: =ROUND(Call_Table_Data[[#This Row],[Satisfaction Rating]],0) -> 5 | N3: C0001 | O3: Male | P3: 41 | Q3: Columbus
A4: Call_7272 | B4: C0004 | C4: 119 | D4: R05 | E4: 44927 | F4: 135 | G4: 2.9 | H4: =IF(MONTH(Call_Table_Data[[#This Row],[Date of Call]])<=3,YEAR(Call_Table_Data[[#This Row],[Date of Call]]),YEAR(Call_Table_Data[[#This Row],[Date of Call]])+1) -> 2023 | I4: =TEXT(Call_Table_Data[[#This Row],[Date of Call]],"DDDD") -> Sunday | J4: {=_xlfn.IFS(Call_Table_Data[[#This Row],[Duration]]<=10,"Under 10 Mins",Call_Table_Data[[#This Row],[Duration]]<=30,"10 to 30 Mins",Call_Table_Data[[#This Row],[Duration]]<=60,"30 to 60 Mins",Call_Table_Data[[#This Row],[Duration]]<=120,"1 to 2 Hours",TRUE,"More Than 2 Hours")} -> 1 to 2 Hours | K4: =ROUND(Call_Table_Data[[#This Row],[Satisfaction Rating]],0) -> 3 | N4: C0002 | O4: Male | P4: 31 | Q4: Cleveland
A5: Call_7273 | B5: C0005 | C5: 68 | D5: R02 | E5: 44927 | F5: 66 | G5: 4.7 | H5: =IF(MONTH(Call_Table_Data[[#This Row],[Date of Call]])<=3,YEAR(Call_Table_Data[[#This Row],[Date of Call]]),YEAR(Call_Table_Data[[#This Row],[Date of Call]])+1) -> 2023 | I5: =TEXT(Call_Table_Data[[#This Row],[Date of Call]],"DDDD") -> Sunday | J5: {=_xlfn.IFS(Call_Table_Data[[#This Row],[Duration]]<=10,"Under 10 Mins",Call_Table_Data[[#This Row],[Duration]]<=30,"10 to 30 Mins",Call_Table_Data[[#This Row],[Duration]]<=60,"30 to 60 Mins",Call_Table_Data[[#This Row],[Duration]]<=120,"1 to 2 Hours",TRUE,"More Than 2 Hours")} -> 1 to 2 Hours | K5: =ROUND(Call_Table_Data[[#This Row],[Satisfaction Rating]],0) -> 5 | N5: C0003 | O5: Male | P5: 26 | Q5: Cincinnati
A6: Call_7274 | B6: C0014 | C6: 119 | D6: R02 | E6: 44927 | F6: 22 | G6: 2.9 | H6: =IF(MONTH(Call_Table_Data[[#This Row],[Date of Call]])<=3,YEAR(Call_Table_Data[[#This Row],[Date of Call]]),YEAR(Call_Table_Data[[#This Row],[Date of Call]])+1) -> 2023 | I6: =TEXT(Call_Table_Data[[#This Row],[Date of Call]],"DDDD") -> Sunday | J6: {=_xlfn.IFS(Call_Table_Data[[#This Row],[Duration]]<=10,"Under 10 Mins",Call_Table_Data[[#This Row],[Duration]]<=30,"10 to 30 Mins",Call_Table_Data[[#This Row],[Duration]]<=60,"30 to 60 Mins",Call_Table_Data[[#This Row],[Duration]]<=120,"1 to 2 Hours",TRUE,"More Than 2 Hours")} -> 1 to 2 Hours | K6: =ROUND(Call_Table_Data[[#This Row],[Satisfaction Rating]],0) -> 3 | N6: C0004 | O6: Male | P6: 36 | Q6: Cincinnati
A7: Call_7275 | B7: C0011 | C7: 128 | D7: R01 | E7: 44928 | F7: 31 | G7: 2.8 | H7: =IF(MONTH(Call_Table_Data[[#This Row],[Date of Call]])<=3,YEAR(Call_Table_Data[[#This Row],[Date of Call]]),YEAR(Call_Table_Data[[#This Row],[Date of Call]])+1) -> 2023 | I7: =TEXT(Call_Table_Data[[#This Row],[Date of Call]],"DDDD") -> Monday | J7: {=_xlfn.IFS(Call_Table_Data[[#This Row],[Duration]]<=10,"Under 10 Mins",Call_Table_Data[[#This Row],[Duration]]<=30,"10 to 30 Mins",Call_Table_Data[[#This Row],[Duration]]<=60,"30 to 60 Mins",Call_Table_Data[[#This Row],[Duration]]<=120,"1 to 2 Hours",TRUE,"More Than 2 Hours")} -> More Than 2 Hours | K7: =ROUND(Call_Table_Data[[#This Row],[Satisfaction Rating]],0) -> 3 | N7: C0005 | O7: Male | P7: 37 | Q7: Columbus
A8: Call_7276 | B8: C0011 | C8: 49 | D8: R02 | E8: 44929 | F8: 135 | G8: 4.8 | H8: =IF(MONTH(Call_Table_Data[[#This Row],[Date of Call]])<=3,YEAR(Call_Table_Data[[#This Row],[Date of Call]]),YEAR(Call_Table_Data[[#This Row],[Date of Call]])+1) -> 2023 | I8: =TEXT(Call_Table_Data[[#This Row],[Date of Call]],"DDDD") -> Tuesday | J8: {=_xlfn.IFS(Call_Table_Data[[#This Row],[Duration]]<=10,"Under 10 Mins",Call_Table_Data[[#This Row],[Duration]]<=30,"10 to 30 Mins",Call_Table_Data[[#This Row],[Duration]]<=60,"30 to 60 Mins",Call_Table_Data[[#This Row],[Duration]]<=120,"1 to 2 Hours",TRUE,"More Than 2 Hours")} -> 30 to 60 Mins | K8: =ROUND(Call_Table_Data[[#This Row],[Satisfaction Rating]],0) -> 5 | N8: C0006 | O8: Male | P8: 23 | Q8: Columbus
A9: Call_7277 | B9: C0007 | C9: 84 | D9: R05 | E9: 44929 | F9: 60 | G9: 4.7 | H9: =IF(MONTH(Call_Table_Data[[#This Row],[Date of Call]])<=3,YEAR(Call_Table_Data[[#This Row],[Date of Call]]),YEAR(Call_Table_Data[[#This Row],[Date of Call]])+1) -> 2023 | I9: =TEXT(Call_Table_Data[[#This Row],[Date of Call]],"DDDD") -> Tuesday | J9: {=_xlfn.IFS(Call_Table_Data[[#This Row],[Duration]]<=10,"Under 10 Mins",Call_Table_Data[[#This Row],[Duration]]<=30,"10 to 30 Mins",Call_Table_Data[[#This Row],[Duration]]<=60,"30 to 60 Mins",Call_Table_Data[[#This Row],[Duration]]<=120,"1 to 2 Hours",TRUE,"More Than 2 Hours")} -> 1 to 2 Hours | K9: =ROUND(Call_Table_Data[[#This Row],[Satisfaction Rating]],0) -> 5 | N9: C0007 | O9: Female | P9: 22 | Q9: Cleveland
A10: Call_7278 | B10: C0003 | C10: 103 | D10: R04 | E10: 44929 | F10: 148 | G10: 4.4 | H10: =IF(MONTH(Call_Table_Data[[#This Row],[Date of Call]])<=3,YEAR(Call_Table_Data[[#This Row],[Date of Call]]),YEAR(Call_Table_Data[[#This Row],[Date of Call]])+1) -> 2023 | I10: =TEXT(Call_Table_Data[[#This Row],[Date of Call]],"DDDD") -> Tuesday | J10: {=_xlfn.IFS(Call_Table_Data[[#This Row],[Duration]]<=10,"Under 10 Mins",Call_Table_Data[[#This Row],[Duration]]<=30,"10 to 30 Mins",Call_Table_Data[[#This Row],[Duration]]<=60,"30 to 60 Mins",Call_Table_Data[[#This Row],[Duration]]<=120,"1 to 2 Hours",TRUE,"More Than 2 Hours")} -> 1 to 2 Hours | K10: =ROUND(Call_Table_Data[[#This Row],[Satisfaction Rating]],0) -> 4 | N10: C0008 | O10: Female | P10: 42 | Q10: Cleveland
A11: Call_7279 | B11: C0005 | C11: 31 | D11: R02 | E11: 44929 | F11: 135 | G11: 3.6 | H11: =IF(MONTH(Call_Table_Data[[#This Row],[Date of Call]])<=3,YEAR(Call_Table_Data[[#This Row],[Date of Call]]),YEAR(Call_Table_Data[[#This Row],[Date of Call]])+1) -> 2023 | I11: =TEXT(Call_Table_Data[[#This Row],[Date of Call]],"DDDD") -> Tuesday | J11: {=_xlfn.IFS(Call_Table_Data[[#This Row],[Duration]]<=10,"Under 10 Mins",Call_Table_Data[[#This Row],[Duration]]<=30,"10 to 30 Mins",Call_Table_Data[[#This Row],[Duration]]<=60,"30 to 60 Mins",Call_Table_Data[[#This Row],[Duration]]<=120,"1 to 2 Hours",TRUE,"More Than 2 Hours")} -> 30 to 60 Mins | K11: =ROUND(Call_Table_Data[[#This Row],[Satisfaction Rating]],0) -> 4 | N11: C0009 | O11: Female | P11: 25 | Q11: Columbus
A12: Call_7280 | B12: C0010 | C12: 44 | D12: R03 | E12: 44929 | F12: 105 | G12: 2.9 | H12: =IF(MONTH(Call_Table_Data[[#This Row],[Date of Call]])<=3,YEAR(Call_Table_Data[[#This Row],[Date of Call]]),YEAR(Call_Table_Data[[#This Row],[Date of Call]])+1) -> 2023 | I12: =TEXT(Call_Table_Data[[#This Row],[Date of Call]],"DDDD") -> Tuesday | J12: {=_xlfn.IFS(Call_Table_Data[[#This Row],[Duration]]<=10,"Under 10 Mins",Call_Table_Data[[#This Row],[Duration]]<=30,"10 to 30 Mins",Call_Table_Data[[#This Row],[Duration]]<=60,"30 to 60 Mins",Call_Table_Data[[#This Row],[Duration]]<=120,"1 to 2 Hours",TRUE,"More Than 2 Hours")} -> 30 to 60 Mins | K12: =ROUND(Call_Table_Data[[#This Row],[Satisfaction Rating]],0) -> 3 | N12: C0010 | O12: Female | P12: 30 | Q12: Cleveland
A13: Call_7281 | B13: C0011 | C13: 102 | D13: R02 | E13: 44929 | F13: 69 | G13: 4.9 | H13: =IF(MONTH(Call_Table_Data[[#This Row],[Date of Call]])<=3,YEAR(Call_Table_Data[[#This Row],[Date of Call]]),YEAR(Call_Table_Data[[#This Row],[Date of Call]])+1) -> 2023 | I13: =TEXT(Call_Table_Data[[#This Row],[Date of Call]],"DDDD") -> Tuesday | J13: {=_xlfn.IFS(Call_Table_Data[[#This Row],[Duration]]<=10,"Under 10 Mins",Call_Table_Data[[#This Row],[Duration]]<=30,"10 to 30 Mins",Call_Table_Data[[#This Row],[Duration]]<=60,"30 to 60 Mins",Call_Table_Data[[#This Row],[Duration]]<=120,"1 to 2 Hours",TRUE,"More Than 2 Hours")} -> 1 to 2 Hours | K13: =ROUND(Call_Table_Data[[#This Row],[Satisfaction Rating]],0) -> 5 | N13: C0011 | O13: Female | P13: 30 | Q13: Cincinnati
A14: Call_7282 | B14: C0013 | C14: 135 | D14: R05 | E14: 44929 | F14: 46 | G14: 3.4 | H14: =IF(MONTH(Call_Table_Data[[#This Row],[Date of Call]])<=3,YEAR(Call_Table_Data[[#This Row],[Date of Call]]),YEAR(Call_Table_Data[[#This Row],[Date of Call]])+1) -> 2023 | I14: =TEXT(Call_Table_Data[[#This Row],[Date of Call]],"DDDD") -> Tuesday | J14: {=_xlfn.IFS(Call_Table_Data[[#This Row],[Duration]]<=10,"Under 10 Mins",Call_Table_Data[[#This Row],[Duration]]<=30,"10 to 30 Mins",Call_Table_Data[[#This Row],[Duration]]<=60,"30 to 60 Mins",Call_Table_Data[[#This Row],[Duration]]<=120,"1 to 2 Hours",TRUE,"More Than 2 Hours")} -> More Than 2 Hours | K14: =ROUND(Call_Table_Data[[#This Row],[Satisfaction Rating]],0) -> 3 | N14: C0012 | O14: Female | P14: 28 | Q14: Cincinnati
... A17: Call_7285 | B17: C0013 | C17: 48 | D17: R01 | E17: 44930 | F17: 68 | G17: 4.9 | H17: =IF(MONTH(Call_Table_Data[[#This Row],[Date of Call]])<=3,YEAR(Call_Table_Data[[#This Row],[Date of Call]]),YEAR(Call_Table_Data[[#This Row],[Date of Call]])+1) -> 2023 | I17: =TEXT(Call_Table_Data[[#This Row],[Date of Call]],"DDDD") -> Wednesday | J17: {=_xlfn.IFS(Call_Table_Data[[#This Row],[Duration]]<=10,"Under 10 Mins",Call_Table_Data[[#This Row],[Duration]]<=30,"10 to 30 Mins",Call_Table_Data[[#This Row],[Duration]]<=60,"30 to 60 Mins",Call_Table_Data[[#This Row],[Duration]]<=120,"1 to 2 Hours",TRUE,"More Than 2 Hours")} -> 30 to 60 Mins | K17: =ROUND(Call_Table_Data[[#This Row],[Satisfaction Rating]],0) -> 5 | N17: C0015 | O17: Female | P17: 43 | Q17: Cleveland
A18: Call_7286 | B18: C0010 | C18: 176 | D18: R05 | E18: 44931 | F18: 24 | G18: 4.8 | H18: =IF(MONTH(Call_Table_Data[[#This Row],[Date of Call]])<=3,YEAR(Call_Table_Data[[#This Row],[Date of Call]]),YEAR(Call_Table_Data[[#This Row],[Date of Call]])+1) -> 2023 | I18: =TEXT(Call_Table_Data[[#This Row],[Date of Call]],"DDDD") -> Thursday | J18: {=_xlfn.IFS(Call_Table_Data[[#This Row],[Duration]]<=10,"Under 10 Mins",Call_Table_Data[[#This Row],[Duration]]<=30,"10 to 30 Mins",Call_Table_Data[[#This Row],[Duration]]<=60,"30 to 60 Mins",Call_Table_Data[[#This Row],[Duration]]<=120,"1 to 2 Hours",TRUE,"More Than 2 Hours")} -> More Than 2 Hours | K18: =ROUND(Call_Table_Data[[#This Row],[Satisfaction Rating]],0) -> 5
A19: Call_7287 | B19: C0010 | C19: 99 | D19: R01 | E19: 44931 | F19: 195 | G19: 3.9 | H19: =IF(MONTH(Call_Table_Data[[#This Row],[Date of Call]])<=3,YEAR(Call_Table_Data[[#This Row],[Date of Call]]),YEAR(Call_Table_Data[[#This Row],[Date of Call]])+1) -> 2023 | I19: =TEXT(Call_Table_Data[[#This Row],[Date of Call]],"DDDD") -> Thursday | J19: {=_xlfn.IFS(Call_Table_Data[[#This Row],[Duration]]<=10,"Under 10 Mins",Call_Table_Data[[#This Row],[Duration]]<=30,"10 to 30 Mins",Call_Table_Data[[#This Row],[Duration]]<=60,"30 to 60 Mins",Call_Table_Data[[#This Row],[Duration]]<=120,"1 to 2 Hours",TRUE,"More Than 2 Hours")} -> 1 to 2 Hours | K19: =ROUND(Call_Table_Data[[#This Row],[Satisfaction Rating]],0) -> 4
A20: Call_7288 | B20: C0009 | C20: 28 | D20: R03 | E20: 44931 | F20: 28 | G20: 3.8 | H20: =IF(MONTH(Call_Table_Data[[#This Row],[Date of Call]])<=3,YEAR(Call_Table_Data[[#This Row],[Date of Call]]),YEAR(Call_Table_Data[[#This Row],[Date of Call]])+1) -> 2023 | I20: =TEXT(Call_Table_Data[[#This Row],[Date of Call]],"DDDD") -> Thursday | J20: {=_xlfn.IFS(Call_Table_Data[[#This Row],[Duration]]<=10,"Under 10 Mins",Call_Table_Data[[#This Row],[Duration]]<=30,"10 to 30 Mins",Call_Table_Data[[#This Row],[Duration]]<=60,"30 to 60 Mins",Call_Table_Data[[#This Row],[Duration]]<=120,"1 to 2 Hours",TRUE,"More Than 2 Hours")} -> 10 to 30 Mins | K20: =ROUND(Call_Table_Data[[#This Row],[Satisfaction Rating]],0) -> 4
A21: Call_7289 | B21: C0007 | C21: 54 | D21: R02 | E21: 44931 | F21: 170 | G21: 4.3 | H21: =IF(MONTH(Call_Table_Data[[#This Row],[Date of Call]])<=3,YEAR(Call_Table_Data[[#This Row],[Date of Call]]),YEAR(Call_Table_Data[[#This Row],[Date of Call]])+1) -> 2023 | I21: =TEXT(Call_Table_Data[[#This Row],[Date of Call]],"DDDD") -> Thursday | J21: {=_xlfn.IFS(Call_Table_Data[[#This Row],[Duration]]<=10,"Under 10 Mins",Call_Table_Data[[#This Row],[Duration]]<=30,"10 to 30 Mins",Call_Table_Data[[#This Row],[Duration]]<=60,"30 to 60 Mins",Call_Table_Data[[#This Row],[Duration]]<=120,"1 to 2 Hours",TRUE,"More Than 2 Hours")} -> 30 to 60 Mins | K21: =ROUND(Call_Table_Data[[#This Row],[Satisfaction Rating]],0) -> 4
A22: Call_7290 | B22: C0006 | C22: 48 | D22: R05 | E22: 44932 | F22: 30 | G22: 4.4 | H22: =IF(MONTH(Call_Table_Data[[#This Row],[Date of Call]])<=3,YEAR(Call_Table_Data[[#This Row],[Date of Call]]),YEAR(Call_Table_Data[[#This Row],[Date of Call]])+1) -> 2023 | I22: =TEXT(Call_Table_Data[[#This Row],[Date of Call]],"DDDD") -> Friday | J22: {=_xlfn.IFS(Call_Table_Data[[#This Row],[Duration]]<=10,"Under 10 Mins",Call_Table_Data[[#This Row],[Duration]]<=30,"10 to 30 Mins",Call_Table_Data[[#This Row],[Duration]]<=60,"30 to 60 Mins",Call_Table_Data[[#This Row],[Duration]]<=120,"1 to 2 Hours",TRUE,"More Than 2 Hours")} -> 30 to 60 Mins | K22: =ROUND(Call_Table_Data[[#This Row],[Satisfaction Rating]],0) -> 4
A23: Call_7291 | B23: C0004 | C23: 128 | D23: R05 | E23: 44932 | F23: 72 | G23: 5 | H23: =IF(MONTH(Call_Table_Data[[#This Row],[Date of Call]])<=3,YEAR(Call_Table_Data[[#This Row],[Date of Call]]),YEAR(Call_Table_Data[[#This Row],[Date of Call]])+1) -> 2023 | I23: =TEXT(Call_Table_Data[[#This Row],[Date of Call]],"DDDD") -> Friday | J23: {=_xlfn.IFS(Call_Table_Data[[#This Row],[Duration]]<=10,"Under 10 Mins",Call_Table_Data[[#This Row],[Duration]]<=30,"10 to 30 Mins",Call_Table_Data[[#This Row],[Duration]]<=60,"30 to 60 Mins",Call_Table_Data[[#This Row],[Duration]]<=120,"1 to 2 Hours",TRUE,"More Than 2 Hours")} -> More Than 2 Hours | K23: =ROUND(Call_Table_Data[[#This Row],[Satisfaction Rating]],0) -> 5
A24: Call_7292 | B24: C0004 | C24: 38 | D24: R04 | E24: 44933 | F24: 92 | G24: 4.9 | H24: =IF(MONTH(Call_Table_Data[[#This Row],[Date of Call]])<=3,YEAR(Call_Table_Data[[#This Row],[Date of Call]]),YEAR(Call_Table_Data[[#This Row],[Date of Call]])+1) -> 2023 | I24: =TEXT(Call_Table_Data[[#This Row],[Date of Call]],"DDDD") -> Saturday | J24: {=_xlfn.IFS(Call_Table_Data[[#This Row],[Duration]]<=10,"Under 10 Mins",Call_Table_Data[[#This Row],[Duration]]<=30,"10 to 30 Mins",Call_Table_Data[[#This Row],[Duration]]<=60,"30 to 60 Mins",Call_Table_Data[[#This Row],[Duration]]<=120,"1 to 2 Hours",TRUE,"More Than 2 Hours")} -> 30 to 60 Mins | K24: =ROUND(Call_Table_Data[[#This Row],[Satisfaction Rating]],0) -> 5
A25: Call_7293 | B25: C0003 | C25: 67 | D25: R04 | E25: 44934 | F25: 165 | G25: 4.5 | H25: =IF(MONTH(Call_Table_Data[[#This Row],[Date of Call]])<=3,YEAR(Call_Table_Data[[#This Row],[Date of Call]]),YEAR(Call_Table_Data[[#This Row],[Date of Call]])+1) -> 2023 | I25: =TEXT(Call_Table_Data[[#This Row],[Date of Call]],"DDDD") -> Sunday | J25: {=_xlfn.IFS(Call_Table_Data[[#This Row],[Duration]]<=10,"Under 10 Mins",Call_Table_Data[[#This Row],[Duration]]<=30,"10 to 30 Mins",Call_Table_Data[[#This Row],[Duration]]<=60,"30 to 60 Mins",Call_Table_Data[[#This Row],[Duration]]<=120,"1 to 2 Hours",TRUE,"More Than 2 Hours")} -> 1 to 2 Hours | K25: =ROUND(Call_Table_Data[[#This Row],[Satisfaction Rating]],0) -> 5
A26: Call_7294 | B26: C0015 | C26: 58 | D26: R02 | E26: 44934 | F26: 140 | G26: 2.1 | H26: =IF(MONTH(Call_Table_Data[[#This Row],[Date of Call]])<=3,YEAR(Call_Table_Data[[#This Row],[Date of Call]]),YEAR(Call_Table_Data[[#This Row],[Date of Call]])+1) -> 2023 | I26: =TEXT(Call_Table_Data[[#This Row],[Date of Call]],"DDDD") -> Sunday | J26: {=_xlfn.IFS(Call_Table_Data[[#This Row],[Duration]]<=10,"Under 10 Mins",Call_Table_Data[[#This Row],[Duration]]<=30,"10 to 30 Mins",Call_Table_Data[[#This Row],[Duration]]<=60,"30 to 60 Mins",Call_Table_Data[[#This Row],[Duration]]<=120,"1 to 2 Hours",TRUE,"More Than 2 Hours")} -> 30 to 60 Mins | K26: =ROUND(Call_Table_Data[[#This Row],[Satisfaction Rating]],0) -> 2
A27: Call_7295 | B27: C0010 | C27: 54 | D27: R01 | E27: 44934 | F27: 111 | G27: 3.3 | H27: =IF(MONTH(Call_Table_Data[[#This Row],[Date of Call]])<=3,YEAR(Call_Table_Data[[#This Row],[Date of Call]]),YEAR(Call_Table_Data[[#This Row],[Date of Call]])+1) -> 2023 | I27: =TEXT(Call_Table_Data[[#This Row],[Date of Call]],"DDDD") -> Sunday | J27: {=_xlfn.IFS(Call_Table_Data[[#This Row],[Duration]]<=10,"Under 10 Mins",Call_Table_Data[[#This Row],[Duration]]<=30,"10 to 30 Mins",Call_Table_Data[[#This Row],[Duration]]<=60,"30 to 60 Mins",Call_Table_Data[[#This Row],[Duration]]<=120,"1 to 2 Hours",TRUE,"More Than 2 Hours")} -> 30 to 60 Mins | K27: =ROUND(Call_Table_Data[[#This Row],[Satisfaction Rating]],0) -> 3
A28: Call_7296 | B28: C0012 | C28: 28 | D28: R05 | E28: 44935 | F28: 63 | G28: 4.1 | H28: =IF(MONTH(Call_Table_Data[[#This Row],[Date of Call]])<=3,YEAR(Call_Table_Data[[#This Row],[Date of Call]]),YEAR(Call_Table_Data[[#This Row],[Date of Call]])+1) -> 2023 | I28: =TEXT(Call_Table_Data[[#This Row],[Date of Call]],"DDDD") -> Monday | J28: {=_xlfn.IFS(Call_Table_Data[[#This Row],[Duration]]<=10,"Under 10 Mins",Call_Table_Data[[#This Row],[Duration]]<=30,"10 to 30 Mins",Call_Table_Data[[#This Row],[Duration]]<=60,"30 to 60 Mins",Call_Table_Data[[#This Row],[Duration]]<=120,"1 to 2 Hours",TRUE,"More Than 2 Hours")} -> 10 to 30 Mins | K28: =ROUND(Call_Table_Data[[#This Row],[Satisfaction Rating]],0) -> 4
A29: Call_7297 | B29: C0002 | C29: 73 | D29: R05 | E29: 44935 | F29: 80 | G29: 4.2 | H29: =IF(MONTH(Call_Table_Data[[#This Row],[Date of Call]])<=3,YEAR(Call_Table_Data[[#This Row],[Date of Call]]),YEAR(Call_Table_Data[[#This Row],[Date of Call]])+1) -> 2023 | I29: =TEXT(Call_Table_Data[[#This Row],[Date of Call]],"DDDD") -> Monday | J29: {=_xlfn.IFS(Call_Table_Data[[#This Row],[Duration]]<=10,"Under 10 Mins",Call_Table_Data[[#This Row],[Duration]]<=30,"10 to 30 Mins",Call_Table_Data[[#This Row],[Duration]]<=60,"30 to 60 Mins",Call_Table_Data[[#This Row],[Duration]]<=120,"1 to 2 Hours",TRUE,"More Than 2 Hours")} -> 1 to 2 Hours | K29: =ROUND(Call_Table_Data[[#This Row],[Satisfaction Rating]],0) -> 4
... A1002: Call_8270 | B1002: C0009 | C1002: 114 | D1002: R01 | E1002: 45291 | F1002: 40 | G1002: 3.9 | H1002: =IF(MONTH(Call_Table_Data[[#This Row],[Date of Call]])<=3,YEAR(Call_Table_Data[[#This Row],[Date of Call]]),YEAR(Call_Table_Data[[#This Row],[Date of Call]])+1) -> 2024 | I1002: =TEXT(Call_Table_Data[[#This Row],[Date of Call]],"DDDD") -> Sunday | J1002: {=_xlfn.IFS(Call_Table_Data[[#This Row],[Duration]]<=10,"Under 10 Mins",Call_Table_Data[[#This Row],[Duration]]<=30,"10 to 30 Mins",Call_Table_Data[[#This Row],[Duration]]<=60,"30 to 60 Mins",Call_Table_Data[[#This Row],[Duration]]<=120,"1 to 2 Hours",TRUE,"More Than 2 Hours")} -> 1 to 2 Hours | K1002: =ROUND(Call_Table_Data[[#This Row],[Satisfaction Rating]],0) -> 4

Sheet Icons_Assests_Notes
A1: S.No | B1: Topics | C1: Sub Topics | D1: Steps | E1: Steps Description | F1: Formula | G1: Uses | H1: AT | I1: AT Sheet
A2: 1 | B2: Set up the Dashboard Page & Theme | D2: 1 | E2: Go to Page Layout --> Set Fonts [Header as Bold and Body as Light] --> Effects Throughout the sheet edition Theme Colour as Slipstream | I2: Call_Data_Table_Sheet
D3: 2 | E3: Background Fill the Dashboard some area as Blured Grey color | I3: Call_Centre_1
A4: 2 | B4: Create PIVOT TABLE for the KPIs (Key Performance Indicator) | D4: 1 | E4: Select any value cell data --> Insert --> PIVOT Table --> Enable the Data Model Check Box (This Feature helps In Combaining the All tables in Sheet + Add Measuture ) Pivot Table created in new Sheet Rename the PIVOT Table in PIVOT TABLE Anaylze Ribbon | G4: All calculations and Analysis for our dashboard generated through the Pivot Table | I4: Call_Data_Table_Sheet PIVOT CALL_Calculations
A5: 3 | B5: PIVOT TABLE CALCULATIONS - Creating the "Data Model" | D5: 1 | E5: Make Relationship Between tables -->Click inside anywhere of PIVOT TABLE --> Go to Analze Pivot Table Ribbon --> Click on Relationship Feature
D6: 2 | E6: In Relationship Mini Window --> Add New Relations between Call Data and Customer Data
D7: 3 | E7: Create Relationship Mini Window --> Map the Table and Its coloumn to make Connections
D8: 4 | E8: Once Created, we can notice that "Add Measure" option when right click on PIVOT TABLE NAME
A9: 4 | B9: POWER PIVOT & DAX Measures | C9: DAX Measures | D9: 1 | E9: Under Measures Wini Window --> Select Table Name Provide Appropriate Measure Name
C10: DAX Formula Language | D10: 1 | E10: Provide DAX Formula --> Check the formula is right | F10: =COUNTROWS(Call_Table_Data) | G10: To Count ROWS of the call table --> Total Calls
D11: 2 | E11: This will add call count formula measure to the table to access in one click calculations Note: This measure can not be drag to anywhere on the fields sections, default to Values section
D12: 3 | E12: Total Amount
D13: 4 | E13: Avgrage Rating
D14: 5 | E14: Calcuate from Total Call Count with rounded 5 star rating
B15: SLICERS | D15: 1 | E15: SLICERS is an mini window are enabled button features to view the data change Note: when active cell is tapped and created sclier only to that table is linked not all other
D16: 2 | E16: Right Click on Slicer active chart --> report connections --> to view and link or unlink the slicer to table
A17: 5 | B17: Dashboard Tiles and Shapes | C17: Rectangle | D17: 1 | E17: Insert Ribbon --> choose Shape | Q17: Rep ID | R17: Rep Image
D18: 2 | E18: Add fill colours, shadows --> outer -->CTRL +1 shows the grapics tool to add 3D | Q18: R01 | R18: #VALUE!
D19: 3 | E19: Do Alignment and font size | Q19: R02 | R19: #VALUE!
C20: Text Box | D20: 1 | E20: Insert Ribbon --> choose Text --> Text BOX | Q20: R03 | R20: #VALUE!
D21: 2 | E21: Add fill colours, shadows --> outer -->CTRL +1 shows the grapics tool to add 3D | Q21: R04 | R21: #VALUE!
D22: 3 | E22: Do Alignment and font size | Q22: R05 | R22: #VALUE!
C23: Lasso Object Select | D23: 1 | E23: Home Ribbon --> Find and Select --> Select Object
D24: 2 | E24: Copy and Paste the whole Layouts
D25: 3 | E25: (Ctrl + Navigations keys) Up Down Right Left key used to move whole object
A26: 6 | B26: Trend Graph | C26: Line Marker Chart | D26: 1 | E26: Insert Ribbon --> Line Chart --> Line Chart with markers
D27: 2 | E27: If need X axis to be shaded Area --> Add Total Call Count again --> Right Click above chart line, click "Change Series Chart Type"
D28: 3 | E28: On Total Call Count2 --> Select dropdown as "Area" and check preview
D29: 4 | E29: Disable fields inside Chart --> Select Chart and PivotChart Analze Ribbon --> Field Button turn off by touching upper portion of the Icon or untick what is no need
D30: 5 | E30: Additional fields can be disabled or add new fields by Tappping on + Icon next to chart box
D31: 6 | E31: Formatting the Chart Grapgh--> CTRL+1 to enable --> Format design
D32: 7 | E32: Follow the Graph Designs -->Count Line Marker Chart
A33: 7 | B33: WeekDay Trend | C33: BAR CHART | D33: 1 | E33: Sorting (Monday to Sunday) --> First Sort A to Z in fields --> Axes Sorting --> Ctrl + 1 --> Axis Option --> enabale the option "Categories in Reverse Order"
D34: 2 | E34: Bar Chart --> Format ribbon --> Send it to Back to set in backside
A35: 8 | B35: Calls and Amount by Rep | D35: 1 | E35: Same graph not used multiple time for same table --> to fix --> just copy paste the graph and click the value graph--> then drag the column in cext cell in that same table
B36: Pivot for Number Crunching, Ranges for Charts | D36: 2 | E36: SET Axes BOUND --> Once Rerversed --> change the AxesFROM 250 to 0 TO 0 to 250, Set BOUND --> MINIMUM is 0 max is defaulted
C37: Custom Format Code | D37: 1 | E37: Right click on curreny Value--> Format Cell --> Custom --> make it sample as 18.34K
C38: If Else | D38: 1 | E38: Pointing cell | F38: =IF(F58=$J$55,G58,"N/A")
C39: Link Table to Chart | D39: 1 | E39: Right Click on Bar chart --> Select Data --> Add Series --> Link the table Column and Its Values
C40: Chart BAR Overlapping | D40: 1 | E40: Select the Bar that Overlapped --> CTRL +1 --> Adjust Series Overlap
...

Sheet PIVOT_Call_Calculation
A1: DAX Formula
A3: Total Call Count | B3: Total Amount | C3: Total Duration | D3: Average Rating | E3: 5 Stared* Ratings
A4: 1000 | B4: 96623 | C4: 89850 | D4: 3.8854 | E4: 307
A10: Adding Slicer
A12: Total Call Count | B12: Total Amount | C12: Total Duration | D12: Average Rating | E12: 5 Stared* Ratings | G12: Slicer Connected to this table
A13: 186 | B13: 16651 | C13: 17807 | D13: 3.8973118 | E13: 62
A20: Total Call Count
A22: Row Labels | B22: Total Call Count | C22: Total Call Count2
A23: Jan | B23: 10 | C23: 10
A24: Feb | B24: 11 | C24: 11
A25: Mar | B25: 30 | C25: 30
A26: Apr | B26: 23 | C26: 23
A27: May | B27: 22 | C27: 22
A28: Jun | B28: 11 | C28: 11
A29: Jul | B29: 17 | C29: 17
A30: Aug | B30: 12 | C30: 12
A31: Sep | B31: 13 | C31: 13
A32: Oct | B32: 15 | C32: 15
A33: Nov | B33: 8 | C33: 8
A34: Dec | B34: 14 | C34: 14
A35: Grand Total | B35: 186 | C35: 186
A38: Week Day Trend
A39: Row Labels | B39: Total Call Count
A40: Sunday | B40: 25
A41: Monday | B41: 23
A42: Tuesday | B42: 28
A43: Wednesday | B43: 29
A44: Thursday | B44: 18
A45: Friday | B45: 29
A46: Saturday | B46: 34
A47: Grand Total | B47: 186
A55: Calls and Amount by Rep | F55: For Graph | I55: Selected Rep | J55: =A66 -> R04
A57: Row Labels | B57: Total Call Count | C57: Total Amount | F57: Rep | G57: Call | H57: Amount | I57: Sell Call | J57: Sell Amount
A58: R01 | B58: 189 | C58: 18415 | F58: {=A58:C62} -> R01 | G58: 189 | H58: 18415 | I58: =IF(F58=$J$55,G58,"N/A") -> N/A | J58: =IF(F58=$J$55,H58,"N/A") -> N/A
A59: R02 | B59: 218 | C59: 20581 | F59: R02 | G59: 218 | H59: 20581 | I59: =IF(F59=$J$55,G59,"N/A") -> N/A | J59: =IF(F59=$J$55,H59,"N/A") -> N/A
A60: R03 | B60: 207 | C60: 20872 | F60: R03 | G60: 207 | H60: 20872 | I60: =IF(F60=$J$55,G60,"N/A") -> N/A | J60: =IF(F60=$J$55,H60,"N/A") -> N/A
A61: R04 | B61: 186 | C61: 16651 | F61: R04 | G61: 186 | H61: 16651 | I61: =IF(F61=$J$55,G61,"N/A") -> 186 | J61: =IF(F61=$J$55,H61,"N/A") -> 16651
A62: R05 | B62: 200 | C62: 20104 | F62: R05 | G62: 200 | H62: 20104 | I62: =IF(F62=$J$55,G62,"N/A") -> N/A | J62: =IF(F62=$J$55,H62,"N/A") -> N/A
A63: Grand Total | B63: 1000 | C63: 96623
A65: Row Labels
...

Sheet Call Center DashBoard_1
I1: CALL CENTER DATA REPORT | S1: END
L16: {=PIVOT_Call_Calculation!B96:F96} -> R01 | M16: R02 | N16: R03 | O16: R04 | P16: R05 | Q16: Total
K17: {=IF(PIVOT_Call_Calculation!A97:G114="","",PIVOT_Call_Calculation!A97:G114)} -> Cincinnati
K18: C0003 | L18: 891 | M18: 1332 | N18: 1282 | O18: 739 | P18: 560 | Q18: 4804
K19: C0004 | L19: 1991 | M19: 1886 | N19: 1206 | O19: 884 | P19: 1722 | Q19: 7689
K20: C0011 | L20: 1163 | M20: 1180 | N20: 1616 | O20: 1043 | P20: 1747 | Q20: 6749
K21: C0012 | L21: 1438 | M21: 1616 | N21: 866 | O21: 829 | P21: 2070 | Q21: 6819
K22: Cleveland
K23: C0002 | L23: 1233 | M23: 223 | N23: 1680 | O23: 990 | P23: 1508 | Q23: 5634
K24: C0007 | L24: 1598 | M24: 1907 | N24: 869 | O24: 1426 | P24: 1416 | Q24: 7216
K25: C0008 | L25: 900 | M25: 1016 | N25: 960 | O25: 940 | P25: 1193 | Q25: 5009
H26: =PIVOT_Call_Calculation!L108 -> #VALUE! | K26: C0010 | L26: 900 | M26: 1470 | N26: 1617 | O26: 1314 | P26: 941 | Q26: 6242
K27: C0013 | L27: 1255 | M27: 516 | N27: 1874 | O27: 1863 | P27: 1722 | Q27: 7230
K28: C0015 | L28: 1138 | M28: 1898 | N28: 1482 | O28: 846 | P28: 1154 | Q28: 6518
K29: Columbus
K30: C0001 | L30: 1655 | M30: 805 | N30: 2263 | O30: 987 | P30: 1075 | Q30: 6785
K31: C0005 | L31: 1104 | M31: 2280 | N31: 1445 | O31: 1722 | P31: 1196 | Q31: 7747
H32: =PIVOT_Call_Calculation!L105 -> Call Rank: 186 | K32: C0006 | L32: 372 | M32: 1818 | N32: 1346 | O32: 1156 | P32: 1484 | Q32: 6176
H33: =PIVOT_Call_Calculation!L104 -> % of Calls: 19% | K33: C0009 | L33: 1415 | M33: 1271 | N33: 1214 | O33: 1135 | P33: 1566 | Q33: 6601
H34: =PIVOT_Call_Calculation!L106 -> Amount Rank: 16651 | K34: C0014 | L34: 1362 | M34: 1363 | N34: 1152 | O34: 777 | P34: 750 | Q34: 5404
A36: END
